Workbook

Sheet REGLAS
A1: ASPECTO | B1: REGLA | C1: ORIGEN | H1: ¿EN QUE RANGO DE EDAD TE ENCUENTRAS?
A2: TOTAL DE REGISTROS | B2: 479 PERSONAS FICTICIAS | C2: SG-04
A3: EDAD PERMITIDA | B3: DE 18 A 28 AÑOS | C3: SG-04 | Y3: =IF(I3="Tengo un emprendimiento o quiero iniciar uno",X3,"")
A4: URBANA CONSOLIDADA | B4: 256 REGISTROS | C4: SG-04 | Y4: =IF(I4="Tengo un emprendimiento o quiero iniciar uno",X4,"")
A5: URBANA PERIFERICA | B5: 113 REGISTROS | C5: SG-04 | Y5: =IF(I5="Tengo un emprendimiento o quiero iniciar uno",X5,"")
A6: CENTROS POBLADOS Y RURAL | B6: 110 REGISTROS | C6: SG-04 | Y6: =IF(I6="Tengo un emprendimiento o quiero iniciar uno",X6,"")
A7: PRUEBA DEL PROFESOR | B7: EXCLUIR LA FILA 3 DE LAHOJA DE RESPUESTAS INICIALES | C7: CONFIRMADO POR EL ESTUDIANTE | Y7: =IF(I7="Tengo un emprendimiento o quiero iniciar uno",X7,"")
A8: RESPUESTAS INICIALES | B8: REFERENCI: NO INCLUIR ENTRE 479 FICTICIAS | C8: HD-01 | Y8: =IF(I8="Tengo un emprendimiento o quiero iniciar uno",X8,"")
A9: UBICACIÓN DE LA EDAD | B9: COLUMNA H DE LA HOJA DE RESPUESTAS INICIALES | C9: ECXEL DE LA ENCUESTA | Y9: =IF(I9="Tengo un emprendimiento o quiero iniciar uno",X9,"")
A10: EDAD FUERA DEL RANGO | B10: FILA 5; 29 AÑOS; NO USAR COMO REFERENCIA DE LA POBLACION DE 18 A 28 AÑOS | C10: REVISION DEL EXCEL | Y10: =IF(I10="Tengo un emprendimiento o quiero iniciar uno",X10,"")
A11: PARTICIPACION NO ACEPTADA | B11: FILA 4; NO ACEPTA PARTICIPAR; EXCLUIR DE LOS DATOS DE REFERENCIA | C11: REVISION DE LA COLUMNA F | Y11: =IF(I11="Tengo un emprendimiento o quiero iniciar uno",X11,"")
A12: UBICACIÓN DE RESIDENCIA | B12: COLUMNA J DE LA HOJA DE RESPUESTAS INICIALES | C12: EXCEL DE LA ENCUESTA | Y12: =IF(I12="Tengo un emprendimiento o quiero iniciar uno",X12,"")
A13: RESPUESTAS DE RESIDENCIA OBSERVADAS | B13: RURAL; URBANO PERIFERICO | C13: REVISION DE LAS RESPUESTAS INICIALES | Y13: =IF(I13="Tengo un emprendimiento o quiero iniciar uno",X13,"")
A14: OPCIONES PERMITIDAS DE RESIDENCIA | B14: URBANO; URBANO PERIFERICO;CENTRO POBLADO; RURAL | C14: FORMULARIO APROBADO | Y14: =IF(I14="Tengo un emprendimiento o quiero iniciar uno",X14,"")
... A135: Dificultades de acceso | B135: Variar opciones individuales y combinadas para los 479 registros. “Ninguna” aparece sola; “Otros” no se utiliza. Se completa aunque sea opcional | C135: Supuesto académico; sin diferencias territoriales impuestas | Y135: =IF(I135="Tengo un emprendimiento o quiero iniciar uno",X135,"")
A136: Servicios conocidos | B136: Una sola respuesta por registro: oficina de orientación laboral; ferias de empleo; programas de emprendimiento; no conozco ninguno. Reparto aproximadamente uniforme; se completa aunque sea opcional | Y136: =IF(I136="Tengo un emprendimiento o quiero iniciar uno",X136,"")
A137: Modalidad preferida | B137: Reparto aproximadamente uniforme entre Presencial, Virtual, Presencial y virtual, y Me es indiferente. Se completa para los 479 registros | C137: Supuesto académico; no representa preferencias reales | Y137: =IF(I137="Tengo un emprendimiento o quiero iniciar uno",X137,"")
A138: Horario preferido | B138: Reparto aproximadamente uniforme entre Diurno, Nocturno, Mañana entre semana y Fines de semana. Se completa para los 479 registros | C138: Supuesto académico; no representa preferencias reales | Y138: =IF(I138="Tengo un emprendimiento o quiero iniciar uno",X138,"")
A139: Medio preferido para recibir información | B139: Reparto aproximadamente uniforme entre WhatsApp, Correo electrónico, Redes sociales y Celular. “Otro” no se utiliza. Se completa para los 479 registros | C139: Supuesto académico; no representa preferencias reales | Y139: =IF(I139="Tengo un emprendimiento o quiero iniciar uno",X139,"")
A140: Alcance del perfil de emprendimiento | B140: Los 39 registros responden preguntas iniciales, emprendimiento y perfilamiento común. J a U quedan vacías por el recorrido simulado; no se interpreta como ausencia de trabajo o búsqueda | C140: Simplificación académica y limitación de la simulación | Y140: =IF(I140="Tengo un emprendimiento o quiero iniciar uno",X140,"")
Y141: =IF(I141="Tengo un emprendimiento o quiero iniciar uno",X141,"")
Y142: =IF(I142="Tengo un emprendimiento o quiero iniciar uno",X142,"")
Y143: =IF(I143="Tengo un emprendimiento o quiero iniciar uno",X143,"")
Y144: =IF(I144="Tengo un emprendimiento o quiero iniciar uno",X144,"")
Y145: =IF(I145="Tengo un emprendimiento o quiero iniciar uno",X145,"")
Y146: =IF(I146="Tengo un emprendimiento o quiero iniciar uno",X146,"")
Y147: =IF(I147="Tengo un emprendimiento o quiero iniciar uno",X147,"")
Y148: =IF(I148="Tengo un emprendimiento o quiero iniciar uno",X148,"")
Y149: =IF(I149="Tengo un emprendimiento o quiero iniciar uno",X149,"")
Y150: =IF(I150="Tengo un emprendimiento o quiero iniciar uno",X150,"")
Y151: =IF(I151="Tengo un emprendimiento o quiero iniciar uno",X151,"")
Y152: =IF(I152="Tengo un emprendimiento o quiero iniciar uno",X152,"")
... Y480: =IF(I480="Tengo un emprendimiento o quiero iniciar uno",X480,"")

Sheet RECORRIDOS
A1: Situación laboral | B1: Preguntas que responde | C1: Preguntas que quedan vacías
A2: Actualmente no trabajo y estoy buscando empleo | B2: Preguntas iniciales 1 a 6; búsqueda de empleo 13 a 18; perfilamiento común desde la 24 | C2: Trabajo actual 7 a 12. Emprendimiento 19 a 23 pendiente de definir según interés
A3: Busco mi primer empleo | B3: Preguntas iniciales 1 a 6; búsqueda de empleo 13 a 18; perfilamiento común desde la 24 | C3: Trabajo actual 7 a 12. Emprendimiento 19 a 23 pendiente de definir según interés
A4: Trabajo actualmente como empleado | B4: Preguntas 1 a 12; búsqueda de empleo 13 a 18 según su situación; perfilamiento común desde la 24 | C4: Emprendimiento 19 a 23: pendiente de definir según interés
A5: Trabajo de manera independiente | B5: Preguntas 1 a 12; búsqueda de empleo 13 a 18 según su situación; perfilamiento común desde la 24 | C5: Emprendimiento 19 a 23: pendiente de definir según interés
A6: Estudio y quiero comenzar a trabajar | B6: Preguntas 1 a 6; búsqueda de empleo 13 a 18; perfilamiento común desde la 24 | C6: Trabajo actual 7 a 12 vacías; emprendimiento 19 a 23 según interés
A7: Tengo un emprendimiento o quiero iniciar uno | B7: Preguntas 1 a 6; emprendimiento 19 a 23; perfilamiento común desde la 24 | C7: Preguntas 7 a 18 sin recoger en este recorrido; situación de empleo adicional desconocida

Sheet RESUMEN TERRITORIAL
A3: DOMINIO TERRITORIAL | B3: PORCENTAJE DE REGISTROS | C3: NUMERO D REGISTROS
A4: CENTROS POBLADOS Y RURAL | B4: 0.22964509 | C4: 110
A5: Urbana Consolidada | B5: 0.53444676 | C5: 256
A6: URBANA PERIFÉRICA | B6: 0.23590814 | C6: 113
A7: Total general | B7: 1 | C7: 479
E20: Dominio territorial | F20: Numero de Registros
E21: Centros Poblados y rural | F21: =C4 -> 110
E22: =A5 -> Urbana Consolidada | F22: =C5 -> 256
E23: Urbana Periferica | F23: =C6 -> 113

Sheet BASE SIMULADA
A1: ID artificial. | B1: Dominio territorial. | C1: ¿Aceptas participar voluntariamente en este formulario y autorizas el uso de la información proporcionada para los fines académicos anteriormente descritos? | D1: ¿Con que género te identificas? | E1: ¿En que rango de edad te encuentras? | F1: ¿Cuál es tu edad? | G1: ¿En qué zona vives actualmente? | H1: ¿Cuál es tu nivel educativo? | I1: ¿Cuál de las siguientes opciones describe mejor tu situación actual? | J1: ¿Cuál describe mejor tu tipo de contrato o trabajo actual? | K1: ¿Cuánto tiempo llevas trabajando? | L1: ¿Tú trabajo está relacionado con tu formación o habilidades? | M1: ¿Qué tan satisfecho/a estás con tus condiciones laborales actuales? | N1: ¿Qué aspecto te gustaría mejorar principalmente de tu situación laboral? | O1: ¿Actualmente estás interesado/a en encontrar un empleo diferente? | P1: ¿Cuánto tiempo llevas buscando empleo? | Q1: ¿Tienes actualmente una hoja de vida actualizada? | R1: ¿Has tenido anteriormente un empleo o trabajo remunerado? | S1: ¿Dónde buscas o buscarias principalmente oportunidades laborales? | T1: ¿Cuál consideras que es tu principal dificultad para conseguir empleo? | U1: ¿Has participado en una entrevista laboral durante los últimos 6 meses? | V1: ¿Cuál describe mejor tu situación? | W1: Si tienes o estás iniciando un emprendimiento, ¿en qué etapa se encuentra? | X1: ¿Cuál es la principal dificultad para iniciar o fortalecer tu emprendimiento? | Y1: ¿Qué tipo de apoyo consideras más importante? | Z1: ¿Has participado anteriormente en algún programa de apoyo al emprendimiento? | AA1: Indica qué tan preparado/a te sientes para realizar las siguientes actividades relacionadas con el empleo..Elaborar o actualizar mi hoja de vida. | AB1: Indica qué tan preparado/a te sientes para realizar las siguientes actividades relacionadas con el empleo..Buscar vacantes por internet. | AC1: Indica qué tan preparado/a te sientes para realizar las siguientes actividades relacionadas con el empleo..Presentarme a una entrevista laboral. | AD1: Indica qué tan preparado/a te sientes para realizar las siguientes actividades relacionadas con el empleo..Explicar mis habilidades y experiencia. | AE1: Indica qué tan preparado/a te sientes para realizar las siguientes actividades relacionadas con el empleo..Utilizar herramientas digitales para trabajar. | AF1: ¿Qué competencias te gustaría fortalecer? | AG1: ¿Qué situaciones dificultan actualmente tu acceso a oportunidades laborales o de formación? | AH1: ¿Cuáles de los siguientes servicios conoces? | AI1: ¿Cómo prefieres participar en actividades de empleabilidad? | AJ1: ¿Qué horario te resulta más conveniente? | AK1: ¿Por qué medio preferirías recibir información sobre oportunidades laborales?
A2: ="SG"&TEXT(ROW()-1,"000") -> SG001 | B2: Urbana Consolidada | C2: SI, ACEPTO PARTICIPAR | D2: =IF(MOD((ROW()-2)*137,479)<230,"Masculino",IF(MOD((ROW()-2)*137,479)<460,"Femenino",IF(MOD((ROW()-2)*137,479)<470,"Otro","No quiero responder"))) -> Masculino | E2: =CHOOSE(MOD(ROW()-2,5)+1,"De 18 a 20 años","De 20 a 22 años","De 22 a 24 años","De 24 a 26 años","De 26 a 28 años") -> De 18 a 20 años | F2: =CHOOSE(MOD(ROW()-2,5)+1,18,20,22,24,26)+MOD(INT((ROW()-2)/5),IF(MOD(ROW()-2,5)=4,3,2)) -> 18 | G2: URBANA | H2: =_xlfn.LET(_xlpm.grupo,MOD(ROW()-2,5),_xlpm.turno,INT((ROW()-2)/5),_xlpm.orden,MOD(_xlpm.turno*37,IF(_xlpm.grupo=4,95,96)),CHOOSE(_xlpm.grupo+1,IF(_xlpm.orden<60,"Bachiller",IF(_xlpm.orden<84,"Técnico","Tecnólogo")),IF(_xlpm.orden<36,"Bachiller",IF(_xlpm.orden<66,"Técnico","Tecnólogo")),IF(_xlpm.orden<24,"Bachiller",IF(_xlpm.orden<48,"Técnico",IF(_xlpm.orden<72,"Tecnólogo","Profesional"))),IF(_xlpm.orden<12,"Bachiller",IF(_xlpm.orden<30,"Técnico",IF(_xlpm.orden<54,"Tecnólogo",IF(_xlpm.orden<90,"Profesional","Posgrado")))),IF(_xlpm.orden<10,"Bachiller",IF(_xlpm.orden<25,"Técnico",IF(_xlpm.orden<45,"Tecnólogo",IF(_xlpm.orden<85,"Profesional","Posgrado")))))) -> Bachiller | I2: =_xlfn.LET(_xlpm.orden,MOD((ROW()-2)*173,479),IF(_xlpm.orden<150,"Trabajo actualmente como empleado",IF(_xlpm.orden<230,"Trabajo de manera independiente",IF(_xlpm.orden<320,"Actualmente no trabajo y estoy buscando empleo",IF(_xlpm.orden<380,"Busco mi primer empleo",IF(_xlpm.orden<440,"Estudio y quiero comenzar a trabajar","Tengo un emprendimiento o quiero iniciar uno")))))) -> Trabajo actualmente como empleado | J2: =IF(I2="Trabajo actualmente como empleado",IF(MOD((COUNTIF($I$2:I2,"Trabajo actualmente como empleado")-1)*37,150)<100,"Empleado con contrato","Empleado sin contrato formal"),IF(I2="Trabajo de manera independiente","Trabajo independiente","")) -> Empleado con contrato | K2: =IF(OR(I2="Trabajo actualmente como empleado",I2="Trabajo de manera independiente"),CHOOSE(MOD(COUNTIF($I$2:I2,I2)-1,4)+1,"Menos de 3 meses","De 3 a 6 meses","De 7 a 12 meses","Más de un año"),"") -> Menos de 3 meses | L2: =IF(OR(I2="Trabajo actualmente como empleado",I2="Trabajo de manera independiente"),CHOOSE(MOD(COUNTIF($I$2:I2,I2)-1,3)+1,"Sí, completamente","Parcialmente","No"),"") -> Sí, completamente | M2: =IF(OR(I2="Trabajo actualmente como empleado",I2="Trabajo de manera independiente"),CHOOSE(MOD(INT((COUNTIF($I$2:I2,I2)-1)/3),4)+1,"1- Muy satisfecho/a","2- Satisfecho/a","3- Insatisfecho/a","4- Muy insatisfecho/a"),"") -> 1- Muy satisfecho/a | N2: =IF(OR(I2="Trabajo actualmente como empleado",I2="Trabajo de manera independiente"),_xlfn.LET(_xlpm.opcion,MOD(INT((COUNTIF($I$2:I2,I2)-1)/5),6)+1,CHOOSE(IF(AND(_xlpm.opcion=6,L2="Sí, completamente"),5,_xlpm.opcion),"Salario","Estabilidad laboral","Horario","Acceso a prestaciones","Oportunidades de crecimiento","Trabajar en un área relacionada con mi formación")),"") -> Salario | O2: =IF(OR(I2="Trabajo actualmente como empleado",I2="Trabajo de manera independiente"),_xlfn.LET(_xlpm.turno,MOD(COUNTIF($I$2:I2,I2)-1,5),_xlpm.nivel,VALUE(LEFT(M2,1)),IF(_xlpm.turno=4,"No estoy seguro/a",IF(_xlpm.turno<IF(_xlpm.nivel<=2,1,3),"Sí","No"))),"") -> Sí | P2: =_xlfn.LET(_xlpm.perfil,I2,_xlpm.turno,COUNTIF($I$2:I2,_xlpm.perfil)-1,_xlpm.busca,OR(_xlpm.perfil="Actualmente no trabajo y estoy buscando empleo",_xlpm.perfil="Busco mi primer empleo"),_xlpm.trabaja,OR(_xlpm.perfil="Trabajo actualmente como empleado",_xlpm.perfil="Trabajo de manera independiente"),IF(_xlpm.busca,CHOOSE(MOD(_xlpm.turno*3,4)+1,"Menos de 1 mes","Entre 1 y 3 meses","Entre 4 y 6 meses","Más de 6 meses"),IF(OR(_xlpm.trabaja,_xlpm.perfil="Estudio y quiero comenzar a trabajar"),IF(AND(_xlpm.trabaja,O2="No"),"Todavía no he iniciado una búsqueda activa",CHOOSE(MOD(_xlpm.turno*3,5)+1,"Menos de 1 mes","Entre 1 y 3 meses","Entre 4 y 6 meses","Más de 6 meses","Todavía no he iniciado una búsqueda activa")),""))) -> Menos de 1 mes | Q2: =IF(I2="Tengo un emprendimiento o quiero iniciar uno","",CHOOSE(MOD(INT((COUNTIF($I$2:I2,I2)-1)/7),3)+1,"Sí","No","Tengo una pero necesito actualizarla")) -> Sí | R2: =IF(I2="Tengo un emprendimiento o quiero iniciar uno","",IF(I2="Busco mi primer empleo","No",IF(MOD(COUNTIF($I$2:I2,I2)-1,2)=0,"Sí","No"))) -> Sí | S2: =IF(I2="Tengo un emprendimiento o quiero iniciar uno","",CHOOSE(MOD(INT((COUNTIF($I$2:I2,I2)-1)/3),10)+1,"Portales de empleo","Redes sociales","Familiares o conocidos","Empresas directamente","Ferias de empleo","Instituciones públicas","Institución educativa","No sé dónde buscar","Portales de empleo;Redes sociales","Familiares o conocidos;Empresas directamente")) -> Portales de empleo | T2: =IF(I2="Tengo un emprendimiento o quiero iniciar uno","",_xlfn.LET(_xlpm.opcion,MOD(INT((COUNTIF($I$2:I2,I2)-1)/4),6)+1,CHOOSE(IF(AND(_xlpm.opcion=3,Q2="Sí"),1,_xlpm.opcion),"Falta de experiencia","Falta de formación","Dificultades con la hoja de vida","Horarios disponibles","Transporte","Internet"))) -> Falta de experiencia | U2: =IF(I2="Tengo un emprendimiento o quiero iniciar uno","",IF(MOD(INT((COUNTIF($I$2:I2,I2)-1)/3),2)=0,"Sí","No")) -> Sí | V2: =IF(I2="Tengo un emprendimiento o quiero iniciar uno",CHOOSE(MOD(COUNTIF($I$2:I2,I2)-1,3)+1,"Tengo un emprendimiento","Estoy iniciando un emprendimiento","Me interesa emprender"),"") | W2: =IF(V2="Tengo un emprendimiento","Funcionamiento estable",IF(V2="Estoy iniciando un emprendimiento","Inicio","")) | X2: =IF(I2="Tengo un emprendimiento o quiero iniciar uno",CHOOSE(MOD(COUNTIF($I$2:I2,I2)-1,5)+1,"Falta de financiación","Falta de conocimientos administrativos","Falta de conocimientos financieros","Falta de tiempo","Falta de herramientas"),"") | Y2: =IF(I2="Tengo un emprendimiento o quiero iniciar uno",X2,"") | Z2: =IF(I2="Tengo un emprendimiento o quiero iniciar uno",CHOOSE(INT(MOD((COUNTIF($I$2:I2,I2)-1)*7,39)/13)+1,"Sí","No","No conozco programas de ese tipo"),"") | AA2: =CHOOSE(INT(MOD((ROW()-2)*191,479)/120)+1,"No puedo hacerlo","Puedo hacerlo con ayuda","Puedo hacerlo con dificultad","Puedo hacerlo sin ayuda") -> No puedo hacerlo | AB2: =CHOOSE(INT(MOD((ROW()-2)*191,479)/120)+1,"No puedo hacerlo","Puedo hacerlo con ayuda","Puedo hacerlo con dificultad","Puedo hacerlo sin ayuda") -> No puedo hacerlo | AC2: =CHOOSE(INT(MOD((ROW()-2)*157+83,479)/120)+1,"No puedo hacerlo","Puedo hacerlo con ayuda","Puedo hacerlo con dificultad","Puedo hacerlo sin ayuda") -> No puedo hacerlo | AD2: =CHOOSE(INT(MOD((ROW()-2)*89+131,479)/120)+1,"No puedo hacerlo","Puedo hacerlo con ayuda","Puedo hacerlo con dificultad","Puedo hacerlo sin ayuda") -> Puedo hacerlo con ayuda | AE2: =CHOOSE(INT(MOD((ROW()-2)*73+179,479)/120)+1,"No puedo hacerlo","Puedo hacerlo con ayuda","Puedo hacerlo con dificultad","Puedo hacerlo sin ayuda") -> Puedo hacerlo con ayuda | AF2: =CHOOSE(MOD((ROW()-2)*61+23,10)+1,"Crear una hoja de vida","Preparación para entrevista","Comunicación","Liderazgo","Emprendimiento","Herramientas digitales","Educación financiera","Crear una hoja de vida;Preparación para entrevista","Comunicación;Liderazgo","Herramientas digitales;Educación financiera") -> Liderazgo | AG2: AH1 | AH2: =CHOOSE(INT(MOD((ROW()-2)*199+59,479)/120)+1,"Oficina de orientación laboral","Ferias de empleo","Programas de emprendimiento","No conozco ninguno") -> Oficina de orientación laboral | AI2: =CHOOSE(INT(MOD((ROW()-2)*127+71,479)/120)+1,"Presencial","Virtual","Presencial y virtual","Me es indiferente") -> Presencial | AJ2: =CHOOSE(INT(MOD((ROW()-2)*163+97,479)/120)+1,"Diurno","Nocturno","Mañana entre semana","Fines de semana") -> Diurno | AK2: =CHOOSE(INT(MOD((ROW()-2)*181+109,479)/120)+1,"WhatsApp","Correo electrónico","Redes sociales","Celular") -> WhatsApp
A3: ="SG"&TEXT(ROW()-1,"000") -> SG002 | B3: Urbana Consolidada | C3: SI, ACEPTO PARTICIPAR | D3: =IF(MOD((ROW()-2)*137,479)<230,"Masculino",IF(MOD((ROW()-2)*137,479)<460,"Femenino",IF(MOD((ROW()-2)*137,479)<470,"Otro","No quiero responder"))) -> Masculino | E3: =CHOOSE(MOD(ROW()-2,5)+1,"De 18 a 20 años","De 20 a 22 años","De 22 a 24 años","De 24 a 26 años","De 26 a 28 años") -> De 20 a 22 años | F3: =CHOOSE(MOD(ROW()-2,5)+1,18,20,22,24,26)+MOD(INT((ROW()-2)/5),IF(MOD(ROW()-2,5)=4,3,2)) -> 20 | G3: URBANA | H3: =_xlfn.LET(_xlpm.grupo,MOD(ROW()-2,5),_xlpm.turno,INT((ROW()-2)/5),_xlpm.orden,MOD(_xlpm.turno*37,IF(_xlpm.grupo=4,95,96)),CHOOSE(_xlpm.grupo+1,IF(_xlpm.orden<60,"Bachiller",IF(_xlpm.orden<84,"Técnico","Tecnólogo")),IF(_xlpm.orden<36,"Bachiller",IF(_xlpm.orden<66,"Técnico","Tecnólogo")),IF(_xlpm.orden<24,"Bachiller",IF(_xlpm.orden<48,"Técnico",IF(_xlpm.orden<72,"Tecnólogo","Profesional"))),IF(_xlpm.orden<12,"Bachiller",IF(_xlpm.orden<30,"Técnico",IF(_xlpm.orden<54,"Tecnólogo",IF(_xlpm.orden<90,"Profesional","Posgrado")))),IF(_xlpm.orden<10,"Bachiller",IF(_xlpm.orden<25,"Técnico",IF(_xlpm.orden<45,"Tecnólogo",IF(_xlpm.orden<85,"Profesional","Posgrado")))))) -> Bachiller | I3: =_xlfn.LET(_xlpm.orden,MOD((ROW()-2)*173,479),IF(_xlpm.orden<150,"Trabajo actualmente como empleado",IF(_xlpm.orden<230,"Trabajo de manera independiente",IF(_xlpm.orden<320,"Actualmente no trabajo y estoy buscando empleo",IF(_xlpm.orden<380,"Busco mi primer empleo",IF(_xlpm.orden<440,"Estudio y quiero comenzar a trabajar","Tengo un emprendimiento o quiero iniciar uno")))))) -> Trabajo de manera independiente | J3: =IF(I3="Trabajo actualmente como empleado",IF(MOD((COUNTIF($I$2:I3,"Trabajo actualmente como empleado")-1)*37,150)<100,"Empleado con contrato","Empleado sin contrato formal"),IF(I3="Trabajo de manera independiente","Trabajo independiente","")) -> Trabajo independiente | K3: =IF(OR(I3="Trabajo actualmente como empleado",I3="Trabajo de manera independiente"),CHOOSE(MOD(COUNTIF($I$2:I3,I3)-1,4)+1,"Menos de 3 meses","De 3 a 6 meses","De 7 a 12 meses","Más de un año"),"") -> Menos de 3 meses | L3: =IF(OR(I3="Trabajo actualmente como empleado",I3="Trabajo de manera independiente"),CHOOSE(MOD(COUNTIF($I$2:I3,I3)-1,3)+1,"Sí, completamente","Parcialmente","No"),"") -> Sí, completamente | M3: =IF(OR(I3="Trabajo actualmente como empleado",I3="Trabajo de manera independiente"),CHOOSE(MOD(INT((COUNTIF($I$2:I3,I3)-1)/3),4)+1,"1- Muy satisfecho/a","2- Satisfecho/a","3- Insatisfecho/a","4- Muy insatisfecho/a"),"") -> 1- Muy satisfecho/a | N3: =IF(OR(I3="Trabajo actualmente como empleado",I3="Trabajo de manera independiente"),_xlfn.LET(_xlpm.opcion,MOD(INT((COUNTIF($I$2:I3,I3)-1)/5),6)+1,CHOOSE(IF(AND(_xlpm.opcion=6,L3="Sí, completamente"),5,_xlpm.opcion),"Salario","Estabilidad laboral","Horario","Acceso a prestaciones","Oportunidades de crecimiento","Trabajar en un área relacionada con mi formación")),"") -> Salario | O3: =IF(OR(I3="Trabajo actualmente como empleado",I3="Trabajo de manera independiente"),_xlfn.LET(_xlpm.turno,MOD(COUNTIF($I$2:I3,I3)-1,5),_xlpm.nivel,VALUE(LEFT(M3,1)),IF(_xlpm.turno=4,"No estoy seguro/a",IF(_xlpm.turno<IF(_xlpm.nivel<=2,1,3),"Sí","No"))),"") -> Sí | P3: =_xlfn.LET(_xlpm.perfil,I3,_xlpm.turno,COUNTIF($I$2:I3,_xlpm.perfil)-1,_xlpm.busca,OR(_xlpm.perfil="Actualmente no trabajo y estoy buscando empleo",_xlpm.perfil="Busco mi primer empleo"),_xlpm.trabaja,OR(_xlpm.perfil="Trabajo actualmente como empleado",_xlpm.perfil="Trabajo de manera independiente"),IF(_xlpm.busca,CHOOSE(MOD(_xlpm.turno*3,4)+1,"Menos de 1 mes","Entre 1 y 3 meses","Entre 4 y 6 meses","Más de 6 meses"),IF(OR(_xlpm.trabaja,_xlpm.perfil="Estudio y quiero comenzar a trabajar"),IF(AND(_xlpm.trabaja,O3="No"),"Todavía no he iniciado una búsqueda activa",CHOOSE(MOD(_xlpm.turno*3,5)+1,"Menos de 1 mes","Entre 1 y 3 meses","Entre 4 y 6 meses","Más de 6 meses","Todavía no he iniciado una búsqueda activa")),""))) -> Menos de 1 mes | Q3: =IF(I3="Tengo un emprendimiento o quiero iniciar uno","",CHOOSE(MOD(INT((COUNTIF($I$2:I3,I3)-1)/7),3)+1,"Sí","No","Tengo una pero necesito actualizarla")) -> Sí | R3: =IF(I3="Tengo un emprendimiento o quiero iniciar uno","",IF(I3="Busco mi primer empleo","No",IF(MOD(COUNTIF($I$2:I3,I3)-1,2)=0,"Sí","No"))) -> Sí | S3: =IF(I3="Tengo un emprendimiento o quiero iniciar uno","",CHOOSE(MOD(INT((COUNTIF($I$2:I3,I3)-1)/3),10)+1,"Portales de empleo","Redes sociales","Familiares o conocidos","Empresas directamente","Ferias de empleo","Instituciones públicas","Institución educativa","No sé dónde buscar","Portales de empleo;Redes sociales","Familiares o conocidos;Empresas directamente")) -> Portales de empleo | T3: =IF(I3="Tengo un emprendimiento o quiero iniciar uno","",_xlfn.LET(_xlpm.opcion,MOD(INT((COUNTIF($I$2:I3,I3)-1)/4),6)+1,CHOOSE(IF(AND(_xlpm.opcion=3,Q3="Sí"),1,_xlpm.opcion),"Falta de experiencia","Falta de formación","Dificultades con la hoja de vida","Horarios disponibles","Transporte","Internet"))) -> Falta de experiencia | U3: =IF(I3="Tengo un emprendimiento o quiero iniciar uno","",IF(MOD(INT((COUNTIF($I$2:I3,I3)-1)/3),2)=0,"Sí","No")) -> Sí | V3: =IF(I3="Tengo un emprendimiento o quiero iniciar uno",CHOOSE(MOD(COUNTIF($I$2:I3,I3)-1,3)+1,"Tengo un emprendimiento","Estoy iniciando un emprendimiento","Me interesa emprender"),"") | W3: =IF(V3="Tengo un emprendimiento","Funcionamiento estable",IF(V3="Estoy iniciando un emprendimiento","Inicio","")) | X3: =IF(I3="Tengo un emprendimiento o quiero iniciar uno",CHOOSE(MOD(COUNTIF($I$2:I3,I3)-1,5)+1,"Falta de financiación","Falta de conocimientos administrativos","Falta de conocimientos financieros","Falta de tiempo","Falta de herramientas"),"") | Y3: =IF(I3="Tengo un emprendimiento o quiero iniciar uno",X3,"") | Z3: =IF(I3="Tengo un emprendimiento o quiero iniciar uno",CHOOSE(INT(MOD((COUNTIF($I$2:I3,I3)-1)*7,39)/13)+1,"Sí","No","No conozco programas de ese tipo"),"") | AA3: =CHOOSE(INT(MOD((ROW()-2)*191,479)/120)+1,"No puedo hacerlo","Puedo hacerlo con ayuda","Puedo hacerlo con dificultad","Puedo hacerlo sin ayuda") -> Puedo hacerlo con ayuda | AB3: =CHOOSE(INT(MOD((ROW()-2)*191,479)/120)+1,"No puedo hacerlo","Puedo hacerlo con ayuda","Puedo hacerlo con dificultad","Puedo hacerlo sin ayuda") -> Puedo hacerlo con ayuda | AC3: =CHOOSE(INT(MOD((ROW()-2)*157+83,479)/120)+1,"No puedo hacerlo","Puedo hacerlo con ayuda","Puedo hacerlo con dificultad","Puedo hacerlo sin ayuda") -> Puedo hacerlo con dificultad | AD3: =CHOOSE(INT(MOD((ROW()-2)*89+131,479)/120)+1,"No puedo hacerlo","Puedo hacerlo con ayuda","Puedo hacerlo con dificultad","Puedo hacerlo sin ayuda") -> Puedo hacerlo con ayuda | AE3: =CHOOSE(INT(MOD((ROW()-2)*73+179,479)/120)+1,"No puedo hacerlo","Puedo hacerlo con ayuda","Puedo hacerlo con dificultad","Puedo hacerlo sin ayuda") -> Puedo hacerlo con dificultad | AF3: =CHOOSE(MOD((ROW()-2)*61+23,10)+1,"Crear una hoja de vida","Preparación para entrevista","Comunicación","Liderazgo","Emprendimiento","Herramientas digitales","Educación financiera","Crear una hoja de vida;Preparación para entrevista","Comunicación;Liderazgo","Herramientas digitales;Educación financiera") -> Emprendimiento | AG3: =CHOOSE(MOD(INT((ROW()-2)/3)*7,9)+1,"Costos de transporte","Distancia","Horarios","Falta de experiencia","Falta de información","Ninguna","Costos de transporte;Distancia","Horarios;Falta de información","Falta de experiencia;Falta de información") -> Costos de transporte | AH3: =CHOOSE(INT(MOD((ROW()-2)*199+59,479)/120)+1,"Oficina de orientación laboral","Ferias de empleo","Programas de emprendimiento","No conozco ninguno") -> Programas de emprendimiento | AI3: =CHOOSE(INT(MOD((ROW()-2)*127+71,479)/120)+1,"Presencial","Virtual","Presencial y virtual","Me es indiferente") -> Virtual | AJ3: =CHOOSE(INT(MOD((ROW()-2)*163+97,479)/120)+1,"Diurno","Nocturno","Mañana entre semana","Fines de semana") -> Mañana entre semana | AK3: =CHOOSE(INT(MOD((ROW()-2)*181+109,479)/120)+1,"WhatsApp","Correo electrónico","Redes sociales","Celular") -> Redes sociales
A4: ="SG"&TEXT(ROW()-1,"000") -> SG003 | B4: Urbana Consolidada | C4: SI, ACEPTO PARTICIPAR | D4: =IF(MOD((ROW()-2)*137,479)<230,"Masculino",IF(MOD((ROW()-2)*137,479)<460,"Femenino",IF(MOD((ROW()-2)*137,479)<470,"Otro","No quiero responder"))) -> Femenino | E4: =CHOOSE(MOD(ROW()-2,5)+1,"De 18 a 20 años","De 20 a 22 años","De 22 a 24 años","De 24 a 26 años","De 26 a 28 años") -> De 22 a 24 años | F4: =CHOOSE(MOD(ROW()-2,5)+1,18,20,22,24,26)+MOD(INT((ROW()-2)/5),IF(MOD(ROW()-2,5)=4,3,2)) -> 22 | G4: URBANA | H4: =_xlfn.LET(_xlpm.grupo,MOD(ROW()-2,5),_xlpm.turno,INT((ROW()-2)/5),_xlpm.orden,MOD(_xlpm.turno*37,IF(_xlpm.grupo=4,95,96)),CHOOSE(_xlpm.grupo+1,IF(_xlpm.orden<60,"Bachiller",IF(_xlpm.orden<84,"Técnico","Tecnólogo")),IF(_xlpm.orden<36,"Bachiller",IF(_xlpm.orden<66,"Técnico","Tecnólogo")),IF(_xlpm.orden<24,"Bachiller",IF(_xlpm.orden<48,"Técnico",IF(_xlpm.orden<72,"Tecnólogo","Profesional"))),IF(_xlpm.orden<12,"Bachiller",IF(_xlpm.orden<30,"Técnico",IF(_xlpm.orden<54,"Tecnólogo",IF(_xlpm.orden<90,"Profesional","Posgrado")))),IF(_xlpm.orden<10,"Bachiller",IF(_xlpm.orden<25,"Técnico",IF(_xlpm.orden<45,"Tecnólogo",IF(_xlpm.orden<85,"Profesional","Posgrado")))))) -> Bachiller | I4: =_xlfn.LET(_xlpm.orden,MOD((ROW()-2)*173,479),IF(_xlpm.orden<150,"Trabajo actualmente como empleado",IF(_xlpm.orden<230,"Trabajo de manera independiente",IF(_xlpm.orden<320,"Actualmente no trabajo y estoy buscando empleo",IF(_xlpm.orden<380,"Busco mi primer empleo",IF(_xlpm.orden<440,"Estudio y quiero comenzar a trabajar","Tengo un emprendimiento o quiero iniciar uno")))))) -> Busco mi primer empleo | J4: =IF(I4="Trabajo actualmente como empleado",IF(MOD((COUNTIF($I$2:I4,"Trabajo actualmente como empleado")-1)*37,150)<100,"Empleado con contrato","Empleado sin contrato formal"),IF(I4="Trabajo de manera independiente","Trabajo independiente","")) | K4: =IF(OR(I4="Trabajo actualmente como empleado",I4="Trabajo de manera independiente"),CHOOSE(MOD(COUNTIF($I$2:I4,I4)-1,4)+1,"Menos de 3 meses","De 3 a 6 meses","De 7 a 12 meses","Más de un año"),"") | L4: =IF(OR(I4="Trabajo actualmente como empleado",I4="Trabajo de manera independiente"),CHOOSE(MOD(COUNTIF($I$2:I4,I4)-1,3)+1,"Sí, completamente","Parcialmente","No"),"") | M4: =IF(OR(I4="Trabajo actualmente como empleado",I4="Trabajo de manera independiente"),CHOOSE(MOD(INT((COUNTIF($I$2:I4,I4)-1)/3),4)+1,"1- Muy satisfecho/a","2- Satisfecho/a","3- Insatisfecho/a","4- Muy insatisfecho/a"),"") | N4: =IF(OR(I4="Trabajo actualmente como empleado",I4="Trabajo de manera independiente"),_xlfn.LET(_xlpm.opcion,MOD(INT((COUNTIF($I$2:I4,I4)-1)/5),6)+1,CHOOSE(IF(AND(_xlpm.opcion=6,L4="Sí, completamente"),5,_xlpm.opcion),"Salario","Estabilidad laboral","Horario","Acceso a prestaciones","Oportunidades de crecimiento","Trabajar en un área relacionada con mi formación")),"") | O4: =IF(OR(I4="Trabajo actualmente como empleado",I4="Trabajo de manera independiente"),_xlfn.LET(_xlpm.turno,MOD(COUNTIF($I$2:I4,I4)-1,5),_xlpm.nivel,VALUE(LEFT(M4,1)),IF(_xlpm.turno=4,"No estoy seguro/a",IF(_xlpm.turno<IF(_xlpm.nivel<=2,1,3),"Sí","No"))),"") | P4: =_xlfn.LET(_xlpm.perfil,I4,_xlpm.turno,COUNTIF($I$2:I4,_xlpm.perfil)-1,_xlpm.busca,OR(_xlpm.perfil="Actualmente no trabajo y estoy buscando empleo",_xlpm.perfil="Busco mi primer empleo"),_xlpm.trabaja,OR(_xlpm.perfil="Trabajo actualmente como empleado",_xlpm.perfil="Trabajo de manera independiente"),IF(_xlpm.busca,CHOOSE(MOD(_xlpm.turno*3,4)+1,"Menos de 1 mes","Entre 1 y 3 meses","Entre 4 y 6 meses","Más de 6 meses"),IF(OR(_xlpm.trabaja,_xlpm.perfil="Estudio y quiero comenzar a trabajar"),IF(AND(_xlpm.trabaja,O4="No"),"Todavía no he iniciado una búsqueda activa",CHOOSE(MOD(_xlpm.turno*3,5)+1,"Menos de 1 mes","Entre 1 y 3 meses","Entre 4 y 6 meses","Más de 6 meses","Todavía no he iniciado una búsqueda activa")),""))) -> Menos de 1 mes | Q4: =IF(I4="Tengo un emprendimiento o quiero iniciar uno","",CHOOSE(MOD(INT((COUNTIF($I$2:I4,I4)-1)/7),3)+1,"Sí","No","Tengo una pero necesito actualizarla")) -> Sí | R4: =IF(I4="Tengo un emprendimiento o quiero iniciar uno","",IF(I4="Busco mi primer empleo","No",IF(MOD(COUNTIF($I$2:I4,I4)-1,2)=0,"Sí","No"))) -> No | S4: =IF(I4="Tengo un emprendimiento o quiero iniciar uno","",CHOOSE(MOD(INT((COUNTIF($I$2:I4,I4)-1)/3),10)+1,"Portales de empleo","Redes sociales","Familiares o conocidos","Empresas directamente","Ferias de empleo","Instituciones públicas","Institución educativa","No sé dónde buscar","Portales de empleo;Redes sociales","Familiares o conocidos;Empresas directamente")) -> Portales de empleo | T4: =IF(I4="Tengo un emprendimiento o quiero iniciar uno","",_xlfn.LET(_xlpm.opcion,MOD(INT((COUNTIF($I$2:I4,I4)-1)/4),6)+1,CHOOSE(IF(AND(_xlpm.opcion=3,Q4="Sí"),1,_xlpm.opcion),"Falta de experiencia","Falta de formación","Dificultades con la hoja de vida","Horarios disponibles","Transporte","Internet"))) -> Falta de experiencia | U4: =IF(I4="Tengo un emprendimiento o quiero iniciar uno","",IF(MOD(INT((COUNTIF($I$2:I4,I4)-1)/3),2)=0,"Sí","No")) -> Sí | V4: =IF(I4="Tengo un emprendimiento o quiero iniciar uno",CHOOSE(MOD(COUNTIF($I$2:I4,I4)-1,3)+1,"Tengo un emprendimiento","Estoy iniciando un emprendimiento","Me interesa emprender"),"") | W4: =IF(V4="Tengo un emprendimiento","Funcionamiento estable",IF(V4="Estoy iniciando un emprendimiento","Inicio","")) | X4: =IF(I4="Tengo un emprendimiento o quiero iniciar uno",CHOOSE(MOD(COUNTIF($I$2:I4,I4)-1,5)+1,"Falta de financiación","Falta de conocimientos administrativos","Falta de conocimientos financieros","Falta de tiempo","Falta de herramientas"),"") | Y4: =IF(I4="Tengo un emprendimiento o quiero iniciar uno",X4,"") | Z4: =IF(I4="Tengo un emprendimiento o quiero iniciar uno",CHOOSE(INT(MOD((COUNTIF($I$2:I4,I4)-1)*7,39)/13)+1,"Sí","No","No conozco programas de ese tipo"),"") | AA4: =CHOOSE(INT(MOD((ROW()-2)*191,479)/120)+1,"No puedo hacerlo","Puedo hacerlo con ayuda","Puedo hacerlo con dificultad","Puedo hacerlo sin ayuda") -> Puedo hacerlo sin ayuda | AB4: =CHOOSE(INT(MOD((ROW()-2)*191,479)/120)+1,"No puedo hacerlo","Puedo hacerlo con ayuda","Puedo hacerlo con dificultad","Puedo hacerlo sin ayuda") -> Puedo hacerlo sin ayuda | AC4: =CHOOSE(INT(MOD((ROW()-2)*157+83,479)/120)+1,"No puedo hacerlo","Puedo hacerlo con ayuda","Puedo hacerlo con dificultad","Puedo hacerlo sin ayuda") -> Puedo hacerlo sin ayuda | AD4: =CHOOSE(INT(MOD((ROW()-2)*89+131,479)/120)+1,"No puedo hacerlo","Puedo hacerlo con ayuda","Puedo hacerlo con dificultad","Puedo hacerlo sin ayuda") -> Puedo hacerlo con dificultad | AE4: =CHOOSE(INT(MOD((ROW()-2)*73+179,479)/120)+1,"No puedo hacerlo","Puedo hacerlo con ayuda","Puedo hacerlo con dificultad","Puedo hacerlo sin ayuda") -> Puedo hacerlo con dificultad | AF4: =CHOOSE(MOD((ROW()-2)*61+23,10)+1,"Crear una hoja de vida","Preparación para entrevista","Comunicación","Liderazgo","Emprendimiento","Herramientas digitales","Educación financiera","Crear una hoja de vida;Preparación para entrevista","Comunicación;Liderazgo","Herramientas digitales;Educación financiera") -> Herramientas digitales | AG4: =CHOOSE(MOD(INT((ROW()-2)/3)*7,9)+1,"Costos de transporte","Distancia","Horarios","Falta de experiencia","Falta de información","Ninguna","Costos de transporte;Distancia","Horarios;Falta de información","Falta de experiencia;Falta de información") -> Costos de transporte | AH4: =CHOOSE(INT(MOD((ROW()-2)*199+59,479)/120)+1,"Oficina de orientación laboral","Ferias de empleo","Programas de emprendimiento","No conozco ninguno") -> No conozco ninguno | AI4: =CHOOSE(INT(MOD((ROW()-2)*127+71,479)/120)+1,"Presencial","Virtual","Presencial y virtual","Me es indiferente") -> Presencial y virtual | AJ4: =CHOOSE(INT(MOD((ROW()-2)*163+97,479)/120)+1,"Diurno","Nocturno","Mañana entre semana","Fines de semana") -> Fines de semana | AK4: =CHOOSE(INT(MOD((ROW()-2)*181+109,479)/120)+1,"WhatsApp","Correo electrónico","Redes sociales","Celular") -> Celular
A5: ="SG"&TEXT(ROW()-1,"000") -> SG004 | B5: Urbana Consolidada | C5: SI, ACEPTO PARTICIPAR | D5: =IF(MOD((ROW()-2)*137,479)<230,"Masculino",IF(MOD((ROW()-2)*137,479)<460,"Femenino",IF(MOD((ROW()-2)*137,479)<470,"Otro","No quiero responder"))) -> Femenino | E5: =CHOOSE(MOD(ROW()-2,5)+1,"De 18 a 20 años","De 20 a 22 años","De 22 a 24 años","De 24 a 26 años","De 26 a 28 años") -> De 24 a 26 años | F5: =CHOOSE(MOD(ROW()-2,5)+1,18,20,22,24,26)+MOD(INT((ROW()-2)/5),IF(MOD(ROW()-2,5)=4,3,2)) -> 24 | G5: URBANA | H5: =_xlfn.LET(_xlpm.grupo,MOD(ROW()-2,5),_xlpm.turno,INT((ROW()-2)/5),_xlpm.orden,MOD(_xlpm.turno*37,IF(_xlpm.grupo=4,95,96)),CHOOSE(_xlpm.grupo+1,IF(_xlpm.orden<60,"Bachiller",IF(_xlpm.orden<84,"Técnico","Tecnólogo")),IF(_xlpm.orden<36,"Bachiller",IF(_xlpm.orden<66,"Técnico","Tecnólogo")),IF(_xlpm.orden<24,"Bachiller",IF(_xlpm.orden<48,"Técnico",IF(_xlpm.orden<72,"Tecnólogo","Profesional"))),IF(_xlpm.orden<12,"Bachiller",IF(_xlpm.orden<30,"Técnico",IF(_xlpm.orden<54,"Tecnólogo",IF(_xlpm.orden<90,"Profesional","Posgrado")))),IF(_xlpm.orden<10,"Bachiller",IF(_xlpm.orden<25,"Técnico",IF(_xlpm.orden<45,"Tecnólogo",IF(_xlpm.orden<85,"Profesional","Posgrado")))))) -> Bachiller | I5: =_xlfn.LET(_xlpm.orden,MOD((ROW()-2)*173,479),IF(_xlpm.orden<150,"Trabajo actualmente como empleado",IF(_xlpm.orden<230,"Trabajo de manera independiente",IF(_xlpm.orden<320,"Actualmente no trabajo y estoy buscando empleo",IF(_xlpm.orden<380,"Busco mi primer empleo",IF(_xlpm.orden<440,"Estudio y quiero comenzar a trabajar","Tengo un emprendimiento o quiero iniciar uno")))))) -> Trabajo actualmente como empleado | J5: =IF(I5="Trabajo actualmente como empleado",IF(MOD((COUNTIF($I$2:I5,"Trabajo actualmente como empleado")-1)*37,150)<100,"Empleado con contrato","Empleado sin contrato formal"),IF(I5="Trabajo de manera independiente","Trabajo independiente","")) -> Empleado con contrato | K5: =IF(OR(I5="Trabajo actualmente como empleado",I5="Trabajo de manera independiente"),CHOOSE(MOD(COUNTIF($I$2:I5,I5)-1,4)+1,"Menos de 3 meses","De 3 a 6 meses","De 7 a 12 meses","Más de un año"),"") -> De 3 a 6 meses | L5: =IF(OR(I5="Trabajo actualmente como empleado",I5="Trabajo de manera independiente"),CHOOSE(MOD(COUNTIF($I$2:I5,I5)-1,3)+1,"Sí, completamente","Parcialmente","No"),"") -> Parcialmente | M5: =IF(OR(I5="Trabajo actualmente como empleado",I5="Trabajo de manera independiente"),CHOOSE(MOD(INT((COUNTIF($I$2:I5,I5)-1)/3),4)+1,"1- Muy satisfecho/a","2- Satisfecho/a","3- Insatisfecho/a","4- Muy insatisfecho/a"),"") -> 1- Muy satisfecho/a | N5: =IF(OR(I5="Trabajo actualmente como empleado",I5="Trabajo de manera independiente"),_xlfn.LET(_xlpm.opcion,MOD(INT((COUNTIF($I$2:I5,I5)-1)/5),6)+1,CHOOSE(IF(AND(_xlpm.opcion=6,L5="Sí, completamente"),5,_xlpm.opcion),"Salario","Estabilidad laboral","Horario","Acceso a prestaciones","Oportunidades de crecimiento","Trabajar en un área relacionada con mi formación")),"") -> Salario | O5: =IF(OR(I5="Trabajo actualmente como empleado",I5="Trabajo de manera independiente"),_xlfn.LET(_xlpm.turno,MOD(COUNTIF($I$2:I5,I5)-1,5),_xlpm.nivel,VALUE(LEFT(M5,1)),IF(_xlpm.turno=4,"No estoy seguro/a",IF(_xlpm.turno<IF(_xlpm.nivel<=2,1,3),"Sí","No"))),"") -> No | P5: =_xlfn.LET(_xlpm.perfil,I5,_xlpm.turno,COUNTIF($I$2:I5,_xlpm.perfil)-1,_xlpm.busca,OR(_xlpm.perfil="Actualmente no trabajo y estoy buscando empleo",_xlpm.perfil="Busco mi primer empleo"),_xlpm.trabaja,OR(_xlpm.perfil="Trabajo actualmente como empleado",_xlpm.perfil="Trabajo de manera independiente"),IF(_xlpm.busca,CHOOSE(MOD(_xlpm.turno*3,4)+1,"Menos de 1 mes","Entre 1 y 3 meses","Entre 4 y 6 meses","Más de 6 meses"),IF(OR(_xlpm.trabaja,_xlpm.perfil="Estudio y quiero comenzar a trabajar"),IF(AND(_xlpm.trabaja,O5="No"),"Todavía no he iniciado una búsqueda activa",CHOOSE(MOD(_xlpm.turno*3,5)+1,"Menos de 1 mes","Entre 1 y 3 meses","Entre 4 y 6 meses","Más de 6 meses","Todavía no he iniciado una búsqueda activa")),""))) -> Todavía no he iniciado una búsqueda activa | Q5: =IF(I5="Tengo un emprendimiento o quiero iniciar uno","",CHOOSE(MOD(INT((COUNTIF($I$2:I5,I5)-1)/7),3)+1,"Sí","No","Tengo una pero necesito actualizarla")) -> Sí | R5: =IF(I5="Tengo un emprendimiento o quiero iniciar uno","",IF(I5="Busco mi primer empleo","No",IF(MOD(COUNTIF($I$2:I5,I5)-1,2)=0,"Sí","No"))) -> No | S5: =IF(I5="Tengo un emprendimiento o quiero iniciar uno","",CHOOSE(MOD(INT((COUNTIF($I$2:I5,I5)-1)/3),10)+1,"Portales de empleo","Redes sociales","Familiares o conocidos","Empresas directamente","Ferias de empleo","Instituciones públicas","Institución educativa","No sé dónde buscar","Portales de empleo;Redes sociales","Familiares o conocidos;Empresas directamente")) -> Portales de empleo | T5: =IF(I5="Tengo un emprendimiento o quiero iniciar uno","",_xlfn.LET(_xlpm.opcion,MOD(INT((COUNTIF($I$2:I5,I5)-1)/4),6)+1,CHOOSE(IF(AND(_xlpm.opcion=3,Q5="Sí"),1,_xlpm.opcion),"Falta de experiencia","Falta de formación","Dificultades con la hoja de vida","Horarios disponibles","Transporte","Internet"))) -> Falta de experiencia | U5: =IF(I5="Tengo un emprendimiento o quiero iniciar uno","",IF(MOD(INT((COUNTIF($I$2:I5,I5)-1)/3),2)=0,"Sí","No")) -> Sí | V5: =IF(I5="Tengo un emprendimiento o quiero iniciar uno",CHOOSE(MOD(COUNTIF($I$2:I5,I5)-1,3)+1,"Tengo un emprendimiento","Estoy iniciando un emprendimiento","Me interesa emprender"),"") | W5: =IF(V5="Tengo un emprendimiento","Funcionamiento estable",IF(V5="Estoy iniciando un emprendimiento","Inicio","")) | X5: =IF(I5="Tengo un emprendimiento o quiero iniciar uno",CHOOSE(MOD(COUNTIF($I$2:I5,I5)-1,5)+1,"Falta de financiación","Falta de conocimientos administrativos","Falta de conocimientos financieros","Falta de tiempo","Falta de herramientas"),"") | Y5: =IF(I5="Tengo un emprendimiento o quiero iniciar uno",X5,"") | Z5: =IF(I5="Tengo un emprendimiento o quiero iniciar uno",CHOOSE(INT(MOD((COUNTIF($I$2:I5,I5)-1)*7,39)/13)+1,"Sí","No","No conozco programas de ese tipo"),"") | AA5: =CHOOSE(INT(MOD((ROW()-2)*191,479)/120)+1,"No puedo hacerlo","Puedo hacerlo con ayuda","Puedo hacerlo con dificultad","Puedo hacerlo sin ayuda") -> No puedo hacerlo | AB5: =CHOOSE(INT(MOD((ROW()-2)*191,479)/120)+1,"No puedo hacerlo","Puedo hacerlo con ayuda","Puedo hacerlo con dificultad","Puedo hacerlo sin ayuda") -> No puedo hacerlo | AC5: =CHOOSE(INT(MOD((ROW()-2)*157+83,479)/120)+1,"No puedo hacerlo","Puedo hacerlo con ayuda","Puedo hacerlo con dificultad","Puedo hacerlo sin ayuda") -> No puedo hacerlo | AD5: =CHOOSE(INT(MOD((ROW()-2)*89+131,479)/120)+1,"No puedo hacerlo","Puedo hacerlo con ayuda","Puedo hacerlo con dificultad","Puedo hacerlo sin ayuda") -> Puedo hacerlo sin ayuda | AE5: =CHOOSE(INT(MOD((ROW()-2)*73+179,479)/120)+1,"No puedo hacerlo","Puedo hacerlo con ayuda","Puedo hacerlo con dificultad","Puedo hacerlo sin ayuda") -> Puedo hacerlo sin ayuda | AF5: =CHOOSE(MOD((ROW()-2)*61+23,10)+1,"Crear una hoja de vida","Preparación para entrevista","Comunicación","Liderazgo","Emprendimiento","Herramientas digitales","Educación financiera","Crear una hoja de vida;Preparación para entrevista","Comunicación;Liderazgo","Herramientas digitales;Educación financiera") -> Educación financiera | AG5: =CHOOSE(MOD(INT((ROW()-2)/3)*7,9)+1,"Costos de transporte","Distancia","Horarios","Falta de experiencia","Falta de información","Ninguna","Costos de transporte;Distancia","Horarios;Falta de información","Falta de experiencia;Falta de información") -> Horarios;Falta de información | AH5: =CHOOSE(INT(MOD((ROW()-2)*199+59,479)/120)+1,"Oficina de orientación laboral","Ferias de empleo","Programas de emprendimiento","No conozco ninguno") -> Ferias de empleo | AI5: =CHOOSE(INT(MOD((ROW()-2)*127+71,479)/120)+1,"Presencial","Virtual","Presencial y virtual","Me es indiferente") -> Me es indiferente | AJ5: =CHOOSE(INT(MOD((ROW()-2)*163+97,479)/120)+1,"Diurno","Nocturno","Mañana entre semana","Fines de semana") -> Diurno | AK5: =CHOOSE(INT(MOD((ROW()-2)*181+109,479)/120)+1,"WhatsApp","Correo electrónico","Redes sociales","Celular") -> Correo electrónico
A6: ="SG"&TEXT(ROW()-1,"000") -> SG005 | B6: Urbana Consolidada | C6: SI, ACEPTO PARTICIPAR | D6: =IF(MOD((ROW()-2)*137,479)<230,"Masculino",IF(MOD((ROW()-2)*137,479)<460,"Femenino",IF(MOD((ROW()-2)*137,479)<470,"Otro","No quiero responder"))) -> Masculino | E6: =CHOOSE(MOD(ROW()-2,5)+1,"De 18 a 20 años","De 20 a 22 años","De 22 a 24 años","De 24 a 26 años","De 26 a 28 años") -> De 26 a 28 años | F6: =CHOOSE(MOD(ROW()-2,5)+1,18,20,22,24,26)+MOD(INT((ROW()-2)/5),IF(MOD(ROW()-2,5)=4,3,2)) -> 26 | G6: URBANA | H6: =_xlfn.LET(_xlpm.grupo,MOD(ROW()-2,5),_xlpm.turno,INT((ROW()-2)/5),_xlpm.orden,MOD(_xlpm.turno*37,IF(_xlpm.grupo=4,95,96)),CHOOSE(_xlpm.grupo+1,IF(_xlpm.orden<60,"Bachiller",IF(_xlpm.orden<84,"Técnico","Tecnólogo")),IF(_xlpm.orden<36,"Bachiller",IF(_xlpm.orden<66,"Técnico","Tecnólogo")),IF(_xlpm.orden<24,"Bachiller",IF(_xlpm.orden<48,"Técnico",IF(_xlpm.orden<72,"Tecnólogo","Profesional"))),IF(_xlpm.orden<12,"Bachiller",IF(_xlpm.orden<30,"Técnico",IF(_xlpm.orden<54,"Tecnólogo",IF(_xlpm.orden<90,"Profesional","Posgrado")))),IF(_xlpm.orden<10,"Bachiller",IF(_xlpm.orden<25,"Técnico",IF(_xlpm.orden<45,"Tecnólogo",IF(_xlpm.orden<85,"Profesional","Posgrado")))))) -> Bachiller | I6: =_xlfn.LET(_xlpm.orden,MOD((ROW()-2)*173,479),IF(_xlpm.orden<150,"Trabajo actualmente como empleado",IF(_xlpm.orden<230,"Trabajo de manera independiente",IF(_xlpm.orden<320,"Actualmente no trabajo y estoy buscando empleo",IF(_xlpm.orden<380,"Busco mi primer empleo",IF(_xlpm.orden<440,"Estudio y quiero comenzar a trabajar","Tengo un emprendimiento o quiero iniciar uno")))))) -> Trabajo de manera independiente | J6: =IF(I6="Trabajo actualmente como empleado",IF(MOD((COUNTIF($I$2:I6,"Trabajo actualmente como empleado")-1)*37,150)<100,"Empleado con contrato","Empleado sin contrato formal"),IF(I6="Trabajo de manera independiente","Trabajo independiente","")) -> Trabajo independiente | K6: =IF(OR(I6="Trabajo actualmente como empleado",I6="Trabajo de manera independiente"),CHOOSE(MOD(COUNTIF($I$2:I6,I6)-1,4)+1,"Menos de 3 meses","De 3 a 6 meses","De 7 a 12 meses","Más de un año"),"") -> De 3 a 6 meses | L6: =IF(OR(I6="Trabajo actualmente como empleado",I6="Trabajo de manera independiente"),CHOOSE(MOD(COUNTIF($I$2:I6,I6)-1,3)+1,"Sí, completamente","Parcialmente","No"),"") -> Parcialmente | M6: =IF(OR(I6="Trabajo actualmente como empleado",I6="Trabajo de manera independiente"),CHOOSE(MOD(INT((COUNTIF($I$2:I6,I6)-1)/3),4)+1,"1- Muy satisfecho/a","2- Satisfecho/a","3- Insatisfecho/a","4- Muy insatisfecho/a"),"") -> 1- Muy satisfecho/a | N6: =IF(OR(I6="Trabajo actualmente como empleado",I6="Trabajo de manera independiente"),_xlfn.LET(_xlpm.opcion,MOD(INT((COUNTIF($I$2:I6,I6)-1)/5),6)+1,CHOOSE(IF(AND(_xlpm.opcion=6,L6="Sí, completamente"),5,_xlpm.opcion),"Salario","Estabilidad laboral","Horario","Acceso a prestaciones","Oportunidades de crecimiento","Trabajar en un área relacionada con mi formación")),"") -> Salario | O6: =IF(OR(I6="Trabajo actualmente como empleado",I6="Trabajo de manera independiente"),_xlfn.LET(_xlpm.turno,MOD(COUNTIF($I$2:I6,I6)-1,5),_xlpm.nivel,VALUE(LEFT(M6,1)),IF(_xlpm.turno=4,"No estoy seguro/a",IF(_xlpm.turno<IF(_xlpm.nivel<=2,1,3),"Sí","No"))),"") -> No | P6: =_xlfn.LET(_xlpm.perfil,I6,_xlpm.turno,COUNTIF($I$2:I6,_xlpm.perfil)-1,_xlpm.busca,OR(_xlpm.perfil="Actualmente no trabajo y estoy buscando empleo",_xlpm.perfil="Busco mi primer empleo"),_xlpm.trabaja,OR(_xlpm.perfil="Trabajo actualmente como empleado",_xlpm.perfil="Trabajo de manera independiente"),IF(_xlpm.busca,CHOOSE(MOD(_xlpm.turno*3,4)+1,"Menos de 1 mes","Entre 1 y 3 meses","Entre 4 y 6 meses","Más de 6 meses"),IF(OR(_xlpm.trabaja,_xlpm.perfil="Estudio y quiero comenzar a trabajar"),IF(AND(_xlpm.trabaja,O6="No"),"Todavía no he iniciado una búsqueda activa",CHOOSE(MOD(_xlpm.turno*3,5)+1,"Menos de 1 mes","Entre 1 y 3 meses","Entre 4 y 6 meses","Más de 6 meses","Todavía no he iniciado una búsqueda activa")),""))) -> Todavía no he iniciado una búsqueda activa | Q6: =IF(I6="Tengo un emprendimiento o quiero iniciar uno","",CHOOSE(MOD(INT((COUNTIF($I$2:I6,I6)-1)/7),3)+1,"Sí","No","Tengo una pero necesito actualizarla")) -> Sí | R6: =IF(I6="Tengo un emprendimiento o quiero iniciar uno","",IF(I6="Busco mi primer empleo","No",IF(MOD(COUNTIF($I$2:I6,I6)-1,2)=0,"Sí","No"))) -> No | S6: =IF(I6="Tengo un emprendimiento o quiero iniciar uno","",CHOOSE(MOD(INT((COUNTIF($I$2:I6,I6)-1)/3),10)+1,"Portales de empleo","Redes sociales","Familiares o conocidos","Empresas directamente","Ferias de empleo","Instituciones públicas","Institución educativa","No sé dónde buscar","Portales de empleo;Redes sociales","Familiares o conocidos;Empresas directamente")) -> Portales de empleo | T6: =IF(I6="Tengo un emprendimiento o quiero iniciar uno","",_xlfn.LET(_xlpm.opcion,MOD(INT((COUNTIF($I$2:I6,I6)-1)/4),6)+1,CHOOSE(IF(AND(_xlpm.opcion=3,Q6="Sí"),1,_xlpm.opcion),"Falta de experiencia","Falta de formación","Dificultades con la hoja de vida","Horarios disponibles","Transporte","Internet"))) -> Falta de experiencia | U6: =IF(I6="Tengo un emprendimiento o quiero iniciar uno","",IF(MOD(INT((COUNTIF($I$2:I6,I6)-1)/3),2)=0,"Sí","No")) -> Sí | V6: =IF(I6="Tengo un emprendimiento o quiero iniciar uno",CHOOSE(MOD(COUNTIF($I$2:I6,I6)-1,3)+1,"Tengo un emprendimiento","Estoy iniciando un emprendimiento","Me interesa emprender"),"") | W6: =IF(V6="Tengo un emprendimiento","Funcionamiento estable",IF(V6="Estoy iniciando un emprendimiento","Inicio","")) | X6: =IF(I6="Tengo un emprendimiento o quiero iniciar uno",CHOOSE(MOD(COUNTIF($I$2:I6,I6)-1,5)+1,"Falta de financiación","Falta de conocimientos administrativos","Falta de conocimientos financieros","Falta de tiempo","Falta de herramientas"),"") | Y6: =IF(I6="Tengo un emprendimiento o quiero iniciar uno",X6,"") | Z6: =IF(I6="Tengo un emprendimiento o quiero iniciar uno",CHOOSE(INT(MOD((COUNTIF($I$2:I6,I6)-1)*7,39)/13)+1,"Sí","No","No conozco programas de ese tipo"),"") | AA6: =CHOOSE(INT(MOD((ROW()-2)*191,479)/120)+1,"No puedo hacerlo","Puedo hacerlo con ayuda","Puedo hacerlo con dificultad","Puedo hacerlo sin ayuda") -> Puedo hacerlo con dificultad | AB6: =CHOOSE(INT(MOD((ROW()-2)*191,479)/120)+1,"No puedo hacerlo","Puedo hacerlo con ayuda","Puedo hacerlo con dificultad","Puedo hacerlo sin ayuda") -> Puedo hacerlo con dificultad | AC6: =CHOOSE(INT(MOD((ROW()-2)*157+83,479)/120)+1,"No puedo hacerlo","Puedo hacerlo con ayuda","Puedo hacerlo con dificultad","Puedo hacerlo sin ayuda") -> Puedo hacerlo con ayuda | AD6: =CHOOSE(INT(MOD((ROW()-2)*89+131,479)/120)+1,"No puedo hacerlo","Puedo hacerlo con ayuda","Puedo hacerlo con dificultad","Puedo hacerlo sin ayuda") -> No puedo hacerlo | AE6: =CHOOSE(INT(MOD((ROW()-2)*73+179,479)/120)+1,"No puedo hacerlo","Puedo hacerlo con ayuda","Puedo hacerlo con dificultad","Puedo hacerlo sin ayuda") -> Puedo hacerlo sin ayuda | AF6: =CHOOSE(MOD((ROW()-2)*61+23,10)+1,"Crear una hoja de vida","Preparación para entrevista","Comunicación","Liderazgo","Emprendimiento","Herramientas digitales","Educación financiera","Crear una hoja de vida;Preparación para entrevista","Comunicación;Liderazgo","Herramientas digitales;Educación financiera") -> Crear una hoja de vida;Preparación para entrevista | AG6: =CHOOSE(MOD(INT((ROW()-2)/3)*7,9)+1,"Costos de transporte","Distancia","Horarios","Falta de experiencia","Falta de información","Ninguna","Costos de transporte;Distancia","Horarios;Falta de información","Falta de experiencia;Falta de información") -> Horarios;Falta de información | AH6: =CHOOSE(INT(MOD((ROW()-2)*199+59,479)/120)+1,"Oficina de orientación laboral","Ferias de empleo","Programas de emprendimiento","No conozco ninguno") -> No conozco ninguno | AI6: =CHOOSE(INT(MOD((ROW()-2)*127+71,479)/120)+1,"Presencial","Virtual","Presencial y virtual","Me es indiferente") -> Presencial | AJ6: =CHOOSE(INT(MOD((ROW()-2)*163+97,479)/120)+1,"Diurno","Nocturno","Mañana entre semana","Fines de semana") -> Mañana entre semana | AK6: =CHOOSE(INT(MOD((ROW()-2)*181+109,479)/120)+1,"WhatsApp","Correo electrónico","Redes sociales","Celular") -> Redes sociales
A7: ="SG"&TEXT(ROW()-1,"000") -> SG006 | B7: Urbana Consolidada | C7: SI, ACEPTO PARTICIPAR | D7: =IF(MOD((ROW()-2)*137,479)<230,"Masculino",IF(MOD((ROW()-2)*137,479)<460,"Femenino",IF(MOD((ROW()-2)*137,479)<470,"Otro","No quiero responder"))) -> Masculino | E7: =CHOOSE(MOD(ROW()-2,5)+1,"De 18 a 20 años","De 20 a 22 años","De 22 a 24 años","De 24 a 26 años","De 26 a 28 años") -> De 18 a 20 años | F7: =CHOOSE(MOD(ROW()-2,5)+1,18,20,22,24,26)+MOD(INT((ROW()-2)/5),IF(MOD(ROW()-2,5)=4,3,2)) -> 19 | G7: URBANA | H7: =_xlfn.LET(_xlpm.grupo,MOD(ROW()-2,5),_xlpm.turno,INT((ROW()-2)/5),_xlpm.orden,MOD(_xlpm.turno*37,IF(_xlpm.grupo=4,95,96)),CHOOSE(_xlpm.grupo+1,IF(_xlpm.orden<60,"Bachiller",IF(_xlpm.orden<84,"Técnico","Tecnólogo")),IF(_xlpm.orden<36,"Bachiller",IF(_xlpm.orden<66,"Técnico","Tecnólogo")),IF(_xlpm.orden<24,"Bachiller",IF(_xlpm.orden<48,"Técnico",IF(_xlpm.orden<72,"Tecnólogo","Profesional"))),IF(_xlpm.orden<12,"Bachiller",IF(_xlpm.orden<30,"Técnico",IF(_xlpm.orden<54,"Tecnólogo",IF(_xlpm.orden<90,"Profesional","Posgrado")))),IF(_xlpm.orden<10,"Bachiller",IF(_xlpm.orden<25,"Técnico",IF(_xlpm.orden<45,"Tecnólogo",IF(_xlpm.orden<85,"Profesional","Posgrado")))))) -> Bachiller | I7: =_xlfn.LET(_xlpm.orden,MOD((ROW()-2)*173,479),IF(_xlpm.orden<150,"Trabajo actualmente como empleado",IF(_xlpm.orden<230,"Trabajo de manera independiente",IF(_xlpm.orden<320,"Actualmente no trabajo y estoy buscando empleo",IF(_xlpm.orden<380,"Busco mi primer empleo",IF(_xlpm.orden<440,"Estudio y quiero comenzar a trabajar","Tengo un emprendimiento o quiero iniciar uno")))))) -> Estudio y quiero comenzar a trabajar | J7: =IF(I7="Trabajo actualmente como empleado",IF(MOD((COUNTIF($I$2:I7,"Trabajo actualmente como empleado")-1)*37,150)<100,"Empleado con contrato","Empleado sin contrato formal"),IF(I7="Trabajo de manera independiente","Trabajo independiente","")) | K7: =IF(OR(I7="Trabajo actualmente como empleado",I7="Trabajo de manera independiente"),CHOOSE(MOD(COUNTIF($I$2:I7,I7)-1,4)+1,"Menos de 3 meses","De 3 a 6 meses","De 7 a 12 meses","Más de un año"),"") | L7: =IF(OR(I7="Trabajo actualmente como empleado",I7="Trabajo de manera independiente"),CHOOSE(MOD(COUNTIF($I$2:I7,I7)-1,3)+1,"Sí, completamente","Parcialmente","No"),"") | M7: =IF(OR(I7="Trabajo actualmente como empleado",I7="Trabajo de manera independiente"),CHOOSE(MOD(INT((COUNTIF($I$2:I7,I7)-1)/3),4)+1,"1- Muy satisfecho/a","2- Satisfecho/a","3- Insatisfecho/a","4- Muy insatisfecho/a"),"") | N7: =IF(OR(I7="Trabajo actualmente como empleado",I7="Trabajo de manera independiente"),_xlfn.LET(_xlpm.opcion,MOD(INT((COUNTIF($I$2:I7,I7)-1)/5),6)+1,CHOOSE(IF(AND(_xlpm.opcion=6,L7="Sí, completamente"),5,_xlpm.opcion),"Salario","Estabilidad laboral","Horario","Acceso a prestaciones","Oportunidades de crecimiento","Trabajar en un área relacionada con mi formación")),"") | O7: =IF(OR(I7="Trabajo actualmente como empleado",I7="Trabajo de manera independiente"),_xlfn.LET(_xlpm.turno,MOD(COUNTIF($I$2:I7,I7)-1,5),_xlpm.nivel,VALUE(LEFT(M7,1)),IF(_xlpm.turno=4,"No estoy seguro/a",IF(_xlpm.turno<IF(_xlpm.nivel<=2,1,3),"Sí","No"))),"") | P7: =_xlfn.LET(_xlpm.perfil,I7,_xlpm.turno,COUNTIF($I$2:I7,_xlpm.perfil)-1,_xlpm.busca,OR(_xlpm.perfil="Actualmente no trabajo y estoy buscando empleo",_xlpm.perfil="Busco mi primer empleo"),_xlpm.trabaja,OR(_xlpm.perfil="Trabajo actualmente como empleado",_xlpm.perfil="Trabajo de manera independiente"),IF(_xlpm.busca,CHOOSE(MOD(_xlpm.turno*3,4)+1,"Menos de 1 mes","Entre 1 y 3 meses","Entre 4 y 6 meses","Más de 6 meses"),IF(OR(_xlpm.trabaja,_xlpm.perfil="Estudio y quiero comenzar a trabajar"),IF(AND(_xlpm.trabaja,O7="No"),"Todavía no he iniciado una búsqueda activa",CHOOSE(MOD(_xlpm.turno*3,5)+1,"Menos de 1 mes","Entre 1 y 3 meses","Entre 4 y 6 meses","Más de 6 meses","Todavía no he iniciado una búsqueda activa")),""))) -> Menos de 1 mes | Q7: =IF(I7="Tengo un emprendimiento o quiero iniciar uno","",CHOOSE(MOD(INT((COUNTIF($I$2:I7,I7)-1)/7),3)+1,"Sí","No","Tengo una pero necesito actualizarla")) -> Sí | R7: =IF(I7="Tengo un emprendimiento o quiero iniciar uno","",IF(I7="Busco mi primer empleo","No",IF(MOD(COUNTIF($I$2:I7,I7)-1,2)=0,"Sí","No"))) -> Sí | S7: =IF(I7="Tengo un emprendimiento o quiero iniciar uno","",CHOOSE(MOD(INT((COUNTIF($I$2:I7,I7)-1)/3),10)+1,"Portales de empleo","Redes sociales","Familiares o conocidos","Empresas directamente","Ferias de empleo","Instituciones públicas","Institución educativa","No sé dónde buscar","Portales de empleo;Redes sociales","Familiares o conocidos;Empresas directamente")) -> Portales de empleo | T7: =IF(I7="Tengo un emprendimiento o quiero iniciar uno","",_xlfn.LET(_xlpm.opcion,MOD(INT((COUNTIF($I$2:I7,I7)-1)/4),6)+1,CHOOSE(IF(AND(_xlpm.opcion=3,Q7="Sí"),1,_xlpm.opcion),"Falta de experiencia","Falta de formación","Dificultades con la hoja de vida","Horarios disponibles","Transporte","Internet"))) -> Falta de experiencia | U7: =IF(I7="Tengo un emprendimiento o quiero iniciar uno","",IF(MOD(INT((COUNTIF($I$2:I7,I7)-1)/3),2)=0,"Sí","No")) -> Sí | V7: =IF(I7="Tengo un emprendimiento o quiero iniciar uno",CHOOSE(MOD(COUNTIF($I$2:I7,I7)-1,3)+1,"Tengo un emprendimiento","Estoy iniciando un emprendimiento","Me interesa emprender"),"") | W7: =IF(V7="Tengo un emprendimiento","Funcionamiento estable",IF(V7="Estoy iniciando un emprendimiento","Inicio","")) | X7: =IF(I7="Tengo un emprendimiento o quiero iniciar uno",CHOOSE(MOD(COUNTIF($I$2:I7,I7)-1,5)+1,"Falta de financiación","Falta de conocimientos administrativos","Falta de conocimientos financieros","Falta de tiempo","Falta de herramientas"),"") | Y7: =IF(I7="Tengo un emprendimiento o quiero iniciar uno",X7,"") | Z7: =IF(I7="Tengo un emprendimiento o quiero iniciar uno",CHOOSE(INT(MOD((COUNTIF($I$2:I7,I7)-1)*7,39)/13)+1,"Sí","No","No conozco programas de ese tipo"),"") | AA7: =CHOOSE(INT(MOD((ROW()-2)*191,479)/120)+1,"No puedo hacerlo","Puedo hacerlo con ayuda","Puedo hacerlo con dificultad","Puedo hacerlo sin ayuda") -> Puedo hacerlo sin ayuda | AB7: =CHOOSE(INT(MOD((ROW()-2)*191,479)/120)+1,"No puedo hacerlo","Puedo hacerlo con ayuda","Puedo hacerlo con dificultad","Puedo hacerlo sin ayuda") -> Puedo hacerlo sin ayuda | AC7: =CHOOSE(INT(MOD((ROW()-2)*157+83,479)/120)+1,"No puedo hacerlo","Puedo hacerlo con ayuda","Puedo hacerlo con dificultad","Puedo hacerlo sin ayuda") -> Puedo hacerlo sin ayuda | AD7: =CHOOSE(INT(MOD((ROW()-2)*89+131,479)/120)+1,"No puedo hacerlo","Puedo hacerlo con ayuda","Puedo hacerlo con dificultad","Puedo hacerlo sin ayuda") -> No puedo hacerlo | AE7: =CHOOSE(INT(MOD((ROW()-2)*73+179,479)/120)+1,"No puedo hacerlo","Puedo hacerlo con ayuda","Puedo hacerlo con dificultad","Puedo hacerlo sin ayuda") -> No puedo hacerlo | AF7: =CHOOSE(MOD((ROW()-2)*61+23,10)+1,"Crear una hoja de vida","Preparación para entrevista","Comunicación","Liderazgo","Emprendimiento","Herramientas digitales","Educación financiera","Crear una hoja de vida;Preparación para entrevista","Comunicación;Liderazgo","Herramientas digitales;Educación financiera") -> Comunicación;Liderazgo | AG7: =CHOOSE(MOD(INT((ROW()-2)/3)*7,9)+1,"Costos de transporte","Distancia","Horarios","Falta de experiencia","Falta de información","Ninguna","Costos de transporte;Distancia","Horarios;Falta de información","Falta de experiencia;Falta de información") -> Horarios;Falta de información | AH7: =CHOOSE(INT(MOD((ROW()-2)*199+59,479)/120)+1,"Oficina de orientación laboral","Ferias de empleo","Programas de emprendimiento","No conozco ninguno") -> Oficina de orientación laboral | AI7: =CHOOSE(INT(MOD((ROW()-2)*127+71,479)/120)+1,"Presencial","Virtual","Presencial y virtual","Me es indiferente") -> Virtual | AJ7: =CHOOSE(INT(MOD((ROW()-2)*163+97,479)/120)+1,"Diurno","Nocturno","Mañana entre semana","Fines de semana") -> Fines de semana | AK7: =CHOOSE(INT(MOD((ROW()-2)*181+109,479)/120)+1,"WhatsApp","Correo electrónico","Redes sociales","Celular") -> WhatsApp
